<mujoco model="ant">
    <include file="./common/skybox.xml"/>
    <include file="./common/visual.xml"/>
    <include file="./common/materials.xml"/>
    
    <compiler inertiafromgeom="true" angle="degree" coordinate="local" />
    <option timestep="0.02" integrator="RK4" />
    
    <default>
        <joint limited="true" armature="1" damping="1" />
        <geom condim="3" conaffinity="0" margin="0.01" friction="1 0.5 0.5" solref=".02 1" solimp=".8 .8 .01" density="5.0" material="self" />
        <default class="wall">
            <geom type="plane" material="decoration"/>
        </default>
    </default>
    
    <worldbody>
        
        <camera name="fixed" pos="0 0 40" quat="1 0 0 0"/>
        
        <geom name="floor" material="grid" pos="0 0 0" size="15 15 .5" type="plane" conaffinity="1" condim="3" />
        <geom name="wall_px" class="wall" pos="-15.7 0 .7" zaxis="1 0 1"  size="1 15 .5"/>
        <geom name="wall_py" class="wall" pos="0 -15.7 .7" zaxis="0 1 1"  size="15 1 .5"/>
        <geom name="wall_nx" class="wall" pos="15.7 0 .7" zaxis="-1 0 1"  size="1 15 .5"/>
        <geom name="wall_ny" class="wall" pos="0 15.7 .7" zaxis="0 -1 1"  size="15 1 .5"/>
        
        <site name="target" type="cylinder" size=".4 .06" pos="0 0 .05" material="target"/>
        
        <body name="torso" pos="-10 -10 0.75">
            <geom name="torso_geom" type="sphere" size="0.25" pos="0 0 0" />
            <joint name="root" type="free" limited="false" pos="0 0 0" axis="0 0 1" margin="0.01" armature="0" damping="0" />
            <camera name="egocentric"  pos=".3 0 .11" xyaxes="0 -1 0 .4 0 1" fovy="60"/>
            <light name="light" pos="0 0 4" mode="trackcom"/>
            
            <body name="front_left_leg" pos="0 0 0">
                <geom name="aux_1_geom" type="capsule" size="0.08" fromto="0.0 0.0 0.0 0.2 0.2 0.0" />
                <body name="aux_1" pos="0.2 0.2 0">
                    <joint name="hip_1" type="hinge" pos="0.0 0.0 0.0" axis="0 0 1" range="-30 30" />
                    <geom name="left_leg_geom" type="capsule" size="0.08" fromto="0.0 0.0 0.0 0.2 0.2 0.0" />
                    <body pos="0.2 0.2 0">
                        <joint name="ankle_1" type="hinge" pos="0.0 0.0 0.0" axis="-1 1 0" range="30 70" />
                        <geom name="left_ankle_geom" type="capsule" size="0.08" fromto="0.0 0.0 0.0 0.4 0.4 0.0" />
                    </body>
                </body>
            </body>
            <body name="front_right_leg" pos="0 0 0">
                <geom name="aux_2_geom" type="capsule" size="0.08" fromto="0.0 0.0 0.0 -0.2 0.2 0.0" />
                <body name="aux_2" pos="-0.2 0.2 0">
                    <joint name="hip_2" type="hinge" pos="0.0 0.0 0.0" axis="0 0 1" range="-30 30" />
                    <geom name="right_leg_geom" type="capsule" size="0.08" fromto="0.0 0.0 0.0 -0.2 0.2 0.0" />
                    <body pos="-0.2 0.2 0">
                        <joint name="ankle_2" type="hinge" pos="0.0 0.0 0.0" axis="1 1 0" range="-70 -30" />
                        <geom name="right_ankle_geom" type="capsule" size="0.08" fromto="0.0 0.0 0.0 -0.4 0.4 0.0" />
                    </body>
                </body>
            </body>
            <body name="back_leg" pos="0 0 0">
                <geom name="aux_3_geom" type="capsule" size="0.08" fromto="0.0 0.0 0.0 -0.2 -0.2 0.0" />
                <body name="aux_3" pos="-0.2 -0.2 0">
                    <joint name="hip_3" type="hinge" pos="0.0 0.0 0.0" axis="0 0 1" range="-30 30" />
                    <geom name="back_leg_geom" type="capsule" size="0.08" fromto="0.0 0.0 0.0 -0.2 -0.2 0.0" />
                    <body pos="-0.2 -0.2 0">
                        <joint name="ankle_3" type="hinge" pos="0.0 0.0 0.0" axis="-1 1 0" range="-70 -30" />
                        <geom name="third_ankle_geom" type="capsule" size="0.08" fromto="0.0 0.0 0.0 -0.4 -0.4 0.0" />
                    </body>
                </body>
            </body>
            <body name="right_back_leg" pos="0 0 0">
                <geom name="aux_4_geom" type="capsule" size="0.08" fromto="0.0 0.0 0.0 0.2 -0.2 0.0" />
                <body name="aux_4" pos="0.2 -0.2 0">
                    <joint name="hip_4" type="hinge" pos="0.0 0.0 0.0" axis="0 0 1" range="-30 30" />
                    <geom name="rightback_leg_geom" type="capsule" size="0.08" fromto="0.0 0.0 0.0 0.2 -0.2 0.0" />
                    <body pos="0.2 -0.2 0">
                        <joint name="ankle_4" type="hinge" pos="0.0 0.0 0.0" axis="1 1 0" range="30 70" />
                        <geom name="fourth_ankle_geom" type="capsule" size="0.08" fromto="0.0 0.0 0.0 0.4 -0.4 0.0" />
                    </body>
                </body>
            </body>
        </body>
    </worldbody>
    
    <actuator>
        <motor joint="hip_4" ctrlrange="-30.0 30.0" ctrllimited="true" />
        <motor joint="ankle_4" ctrlrange="-30.0 30.0" ctrllimited="true" />
        <motor joint="hip_1" ctrlrange="-30.0 30.0" ctrllimited="true" />
        <motor joint="ankle_1" ctrlrange="-30.0 30.0" ctrllimited="true" />
        <motor joint="hip_2" ctrlrange="-30.0 30.0" ctrllimited="true" />
        <motor joint="ankle_2" ctrlrange="-30.0 30.0" ctrllimited="true" />
        <motor joint="hip_3" ctrlrange="-30.0 30.0" ctrllimited="true" />
        <motor joint="ankle_3" ctrlrange="-30.0 30.0" ctrllimited="true" />
    </actuator>
</mujoco>